Internal Server Error: /contact
Traceback (most recent call last):
  File "D:\Djnago_pwh\github_portfolio\django-tailwind-blog-main\portfolio_venv\Lib\site-packages\django\core\handlers\exception.py", line 55, in inner
    response = get_response(request)
               ^^^^^^^^^^^^^^^^^^^^^
  File "D:\Djnago_pwh\github_portfolio\django-tailwind-blog-main\portfolio_venv\Lib\site-packages\django\core\handlers\base.py", line 197, in _get_response
    response = wrapped_callback(request, *callback_args, **callback_kwargs)
               ^^^^^^^^^^^^^^^^^^^^^^^^^^^^^^^^^^^^^^^^^^^^^^^^^^^^^^^^^^^^
  File "D:\Djnago_pwh\github_portfolio\django-tailwind-blog-main\home\views.py", line 50, in contact
    send_mail('You got a mail!', message, '', ['collegerepo2023@gmail.com'])
  File "D:\Djnago_pwh\github_portfolio\django-tailwind-blog-main\portfolio_venv\Lib\site-packages\django\core\mail\__init__.py", line 87, in send_mail
    return mail.send()
           ^^^^^^^^^^^
  File "D:\Djnago_pwh\github_portfolio\django-tailwind-blog-main\portfolio_venv\Lib\site-packages\django\core\mail\message.py", line 298, in send
    return self.get_connection(fail_silently).send_messages([self])
           ^^^^^^^^^^^^^^^^^^^^^^^^^^^^^^^^^^^^^^^^^^^^^^^^^^^^^^^^
  File "D:\Djnago_pwh\github_portfolio\django-tailwind-blog-main\portfolio_venv\Lib\site-packages\django\core\mail\backends\smtp.py", line 124, in send_messages
    new_conn_created = self.open()
                       ^^^^^^^^^^^
  File "D:\Djnago_pwh\github_portfolio\django-tailwind-blog-main\portfolio_venv\Lib\site-packages\django\core\mail\backends\smtp.py", line 91, in open
    self.connection.login(self.username, self.password)
  File "C:\Users\HP\AppData\Local\Programs\Python\Python311\Lib\smtplib.py", line 750, in login
    raise last_exception
  File "C:\Users\HP\AppData\Local\Programs\Python\Python311\Lib\smtplib.py", line 739, in login
    (code, resp) = self.auth(
                   ^^^^^^^^^^
  File "C:\Users\HP\AppData\Local\Programs\Python\Python311\Lib\smtplib.py", line 662, in auth
    raise SMTPAuthenticationError(code, resp)
smtplib.SMTPAuthenticationError: (535, b'5.7.8 Username and Password not accepted. For more information, go to\n5.7.8  https://support.google.com/mail/?p=BadCredentials jj12-20020a170903048c00b001e2461c52c6sm8169881plb.149 - gsmtp')
"POST /contact HTTP/1.1" 500 107699
Internal Server Error: /contact
Traceback (most recent call last):
  File "D:\Djnago_pwh\github_portfolio\django-tailwind-blog-main\portfolio_venv\Lib\site-packages\django\core\handlers\exception.py", line 55, in inner
    response = get_response(request)
               ^^^^^^^^^^^^^^^^^^^^^
  File "D:\Djnago_pwh\github_portfolio\django-tailwind-blog-main\portfolio_venv\Lib\site-packages\django\core\handlers\base.py", line 197, in _get_response
    response = wrapped_callback(request, *callback_args, **callback_kwargs)
               ^^^^^^^^^^^^^^^^^^^^^^^^^^^^^^^^^^^^^^^^^^^^^^^^^^^^^^^^^^^^
  File "D:\Djnago_pwh\github_portfolio\django-tailwind-blog-main\home\views.py", line 50, in contact
    send_mail('You got a mail!', message, '', ['collegerepo2023@gmail.com'])
  File "D:\Djnago_pwh\github_portfolio\django-tailwind-blog-main\portfolio_venv\Lib\site-packages\django\core\mail\__init__.py", line 87, in send_mail
    return mail.send()
           ^^^^^^^^^^^
  File "D:\Djnago_pwh\github_portfolio\django-tailwind-blog-main\portfolio_venv\Lib\site-packages\django\core\mail\message.py", line 298, in send
    return self.get_connection(fail_silently).send_messages([self])
           ^^^^^^^^^^^^^^^^^^^^^^^^^^^^^^^^^^^^^^^^^^^^^^^^^^^^^^^^
  File "D:\Djnago_pwh\github_portfolio\django-tailwind-blog-main\portfolio_venv\Lib\site-packages\django\core\mail\backends\smtp.py", line 124, in send_messages
    new_conn_created = self.open()
                       ^^^^^^^^^^^
  File "D:\Djnago_pwh\github_portfolio\django-tailwind-blog-main\portfolio_venv\Lib\site-packages\django\core\mail\backends\smtp.py", line 91, in open
    self.connection.login(self.username, self.password)
  File "C:\Users\HP\AppData\Local\Programs\Python\Python311\Lib\smtplib.py", line 750, in login
    raise last_exception
  File "C:\Users\HP\AppData\Local\Programs\Python\Python311\Lib\smtplib.py", line 739, in login
    (code, resp) = self.auth(
                   ^^^^^^^^^^
  File "C:\Users\HP\AppData\Local\Programs\Python\Python311\Lib\smtplib.py", line 662, in auth
    raise SMTPAuthenticationError(code, resp)
smtplib.SMTPAuthenticationError: (535, b'5.7.8 Username and Password not accepted. For more information, go to\n5.7.8  https://support.google.com/mail/?p=BadCredentials gx15-20020a056a001e0f00b006e71aec34a8sm7502817pfb.167 - gsmtp')
"POST /contact HTTP/1.1" 500 107830
Internal Server Error: /contact
Traceback (most recent call last):
  File "D:\Djnago_pwh\github_portfolio\django-tailwind-blog-main\portfolio_venv\Lib\site-packages\django\core\handlers\exception.py", line 55, in inner
    response = get_response(request)
               ^^^^^^^^^^^^^^^^^^^^^
  File "D:\Djnago_pwh\github_portfolio\django-tailwind-blog-main\portfolio_venv\Lib\site-packages\django\core\handlers\base.py", line 197, in _get_response
    response = wrapped_callback(request, *callback_args, **callback_kwargs)
               ^^^^^^^^^^^^^^^^^^^^^^^^^^^^^^^^^^^^^^^^^^^^^^^^^^^^^^^^^^^^
  File "D:\Djnago_pwh\github_portfolio\django-tailwind-blog-main\home\views.py", line 50, in contact
    send_mail('You got a mail!', message, '', ['collegerepo2023@gmail.com'])
  File "D:\Djnago_pwh\github_portfolio\django-tailwind-blog-main\portfolio_venv\Lib\site-packages\django\core\mail\__init__.py", line 87, in send_mail
    return mail.send()
           ^^^^^^^^^^^
  File "D:\Djnago_pwh\github_portfolio\django-tailwind-blog-main\portfolio_venv\Lib\site-packages\django\core\mail\message.py", line 298, in send
    return self.get_connection(fail_silently).send_messages([self])
           ^^^^^^^^^^^^^^^^^^^^^^^^^^^^^^^^^^^^^^^^^^^^^^^^^^^^^^^^
  File "D:\Djnago_pwh\github_portfolio\django-tailwind-blog-main\portfolio_venv\Lib\site-packages\django\core\mail\backends\smtp.py", line 124, in send_messages
    new_conn_created = self.open()
                       ^^^^^^^^^^^
  File "D:\Djnago_pwh\github_portfolio\django-tailwind-blog-main\portfolio_venv\Lib\site-packages\django\core\mail\backends\smtp.py", line 91, in open
    self.connection.login(self.username, self.password)
  File "C:\Users\HP\AppData\Local\Programs\Python\Python311\Lib\smtplib.py", line 750, in login
    raise last_exception
  File "C:\Users\HP\AppData\Local\Programs\Python\Python311\Lib\smtplib.py", line 739, in login
    (code, resp) = self.auth(
                   ^^^^^^^^^^
  File "C:\Users\HP\AppData\Local\Programs\Python\Python311\Lib\smtplib.py", line 662, in auth
    raise SMTPAuthenticationError(code, resp)
smtplib.SMTPAuthenticationError: (535, b'5.7.8 Username and Password not accepted. For more information, go to\n5.7.8  https://support.google.com/mail/?p=BadCredentials sn11-20020a17090b2e8b00b002a71f11ddd4sm5318012pjb.15 - gsmtp')
"POST /contact HTTP/1.1" 500 107823
Internal Server Error: /contact
Traceback (most recent call last):
  File "D:\Djnago_pwh\github_portfolio\django-tailwind-blog-main\portfolio_venv\Lib\site-packages\django\core\handlers\exception.py", line 55, in inner
    response = get_response(request)
               ^^^^^^^^^^^^^^^^^^^^^
  File "D:\Djnago_pwh\github_portfolio\django-tailwind-blog-main\portfolio_venv\Lib\site-packages\django\core\handlers\base.py", line 197, in _get_response
    response = wrapped_callback(request, *callback_args, **callback_kwargs)
               ^^^^^^^^^^^^^^^^^^^^^^^^^^^^^^^^^^^^^^^^^^^^^^^^^^^^^^^^^^^^
  File "D:\Djnago_pwh\github_portfolio\django-tailwind-blog-main\home\views.py", line 50, in contact
    send_mail('You got a mail!', message, '', ['rohitthakan2001@gmail.com'])
  File "D:\Djnago_pwh\github_portfolio\django-tailwind-blog-main\portfolio_venv\Lib\site-packages\django\core\mail\__init__.py", line 87, in send_mail
    return mail.send()
           ^^^^^^^^^^^
  File "D:\Djnago_pwh\github_portfolio\django-tailwind-blog-main\portfolio_venv\Lib\site-packages\django\core\mail\message.py", line 298, in send
    return self.get_connection(fail_silently).send_messages([self])
           ^^^^^^^^^^^^^^^^^^^^^^^^^^^^^^^^^^^^^^^^^^^^^^^^^^^^^^^^
  File "D:\Djnago_pwh\github_portfolio\django-tailwind-blog-main\portfolio_venv\Lib\site-packages\django\core\mail\backends\smtp.py", line 124, in send_messages
    new_conn_created = self.open()
                       ^^^^^^^^^^^
  File "D:\Djnago_pwh\github_portfolio\django-tailwind-blog-main\portfolio_venv\Lib\site-packages\django\core\mail\backends\smtp.py", line 91, in open
    self.connection.login(self.username, self.password)
  File "C:\Users\HP\AppData\Local\Programs\Python\Python311\Lib\smtplib.py", line 750, in login
    raise last_exception
  File "C:\Users\HP\AppData\Local\Programs\Python\Python311\Lib\smtplib.py", line 739, in login
    (code, resp) = self.auth(
                   ^^^^^^^^^^
  File "C:\Users\HP\AppData\Local\Programs\Python\Python311\Lib\smtplib.py", line 662, in auth
    raise SMTPAuthenticationError(code, resp)
smtplib.SMTPAuthenticationError: (535, b'5.7.8 Username and Password not accepted. For more information, go to\n5.7.8  https://support.google.com/mail/?p=BadCredentials h10-20020a63e14a000000b005f3c5cf33b5sm7528194pgk.37 - gsmtp')
"POST /contact HTTP/1.1" 500 107726
Internal Server Error: /contact
Traceback (most recent call last):
  File "D:\Djnago_pwh\github_portfolio\django-tailwind-blog-main\portfolio_venv\Lib\site-packages\django\core\handlers\exception.py", line 55, in inner
    response = get_response(request)
               ^^^^^^^^^^^^^^^^^^^^^
  File "D:\Djnago_pwh\github_portfolio\django-tailwind-blog-main\portfolio_venv\Lib\site-packages\django\core\handlers\base.py", line 197, in _get_response
    response = wrapped_callback(request, *callback_args, **callback_kwargs)
               ^^^^^^^^^^^^^^^^^^^^^^^^^^^^^^^^^^^^^^^^^^^^^^^^^^^^^^^^^^^^
  File "D:\Djnago_pwh\github_portfolio\django-tailwind-blog-main\home\views.py", line 74, in contact
    if validate_email(email, verify=True):  # Verify the email
       ^^^^^^^^^^^^^^^^^^^^^^^^^^^^^^^^^^
  File "D:\Djnago_pwh\github_portfolio\django-tailwind-blog-main\portfolio_venv\Lib\site-packages\validate_email.py", line 131, in validate_email
    raise Exception('For check the mx records or check if the email exists you must '
Exception: For check the mx records or check if the email exists you must have installed pyDNS python package
"POST /contact HTTP/1.1" 500 76758
Internal Server Error: /contact
Traceback (most recent call last):
  File "D:\Djnago_pwh\github_portfolio\django-tailwind-blog-main\portfolio_venv\Lib\site-packages\django\core\handlers\exception.py", line 55, in inner
    response = get_response(request)
               ^^^^^^^^^^^^^^^^^^^^^
  File "D:\Djnago_pwh\github_portfolio\django-tailwind-blog-main\portfolio_venv\Lib\site-packages\django\core\handlers\base.py", line 197, in _get_response
    response = wrapped_callback(request, *callback_args, **callback_kwargs)
               ^^^^^^^^^^^^^^^^^^^^^^^^^^^^^^^^^^^^^^^^^^^^^^^^^^^^^^^^^^^^
  File "D:\Djnago_pwh\github_portfolio\django-tailwind-blog-main\home\views.py", line 74, in contact
    if validate_email(email, check_mx=True, smtp_timeout=10, verify=True):
       ^^^^^^^^^^^^^^^^^^^^^^^^^^^^^^^^^^^^^^^^^^^^^^^^^^^^^^^^^^^^^^^^^^
  File "D:\Djnago_pwh\github_portfolio\django-tailwind-blog-main\portfolio_venv\Lib\site-packages\validate_email.py", line 131, in validate_email
    raise Exception('For check the mx records or check if the email exists you must '
Exception: For check the mx records or check if the email exists you must have installed pyDNS python package
"POST /contact HTTP/1.1" 500 76782
Internal Server Error: /contact
Traceback (most recent call last):
  File "D:\Djnago_pwh\github_portfolio\django-tailwind-blog-main\portfolio_venv\Lib\site-packages\django\core\handlers\exception.py", line 55, in inner
    response = get_response(request)
               ^^^^^^^^^^^^^^^^^^^^^
  File "D:\Djnago_pwh\github_portfolio\django-tailwind-blog-main\portfolio_venv\Lib\site-packages\django\core\handlers\base.py", line 197, in _get_response
    response = wrapped_callback(request, *callback_args, **callback_kwargs)
               ^^^^^^^^^^^^^^^^^^^^^^^^^^^^^^^^^^^^^^^^^^^^^^^^^^^^^^^^^^^^
  File "D:\Djnago_pwh\github_portfolio\django-tailwind-blog-main\home\views.py", line 74, in contact
    if validate_email(email, check_mx=True, smtp_timeout=10, verify=True):
       ^^^^^^^^^^^^^^^^^^^^^^^^^^^^^^^^^^^^^^^^^^^^^^^^^^^^^^^^^^^^^^^^^^
  File "D:\Djnago_pwh\github_portfolio\django-tailwind-blog-main\portfolio_venv\Lib\site-packages\validate_email.py", line 131, in validate_email
    raise Exception('For check the mx records or check if the email exists you must '
Exception: For check the mx records or check if the email exists you must have installed pyDNS python package
"POST /contact HTTP/1.1" 500 76913
Internal Server Error: /contact
Traceback (most recent call last):
  File "D:\Djnago_pwh\github_portfolio\django-tailwind-blog-main\portfolio_venv\Lib\site-packages\django\core\handlers\exception.py", line 55, in inner
    response = get_response(request)
               ^^^^^^^^^^^^^^^^^^^^^
  File "D:\Djnago_pwh\github_portfolio\django-tailwind-blog-main\portfolio_venv\Lib\site-packages\django\core\handlers\base.py", line 197, in _get_response
    response = wrapped_callback(request, *callback_args, **callback_kwargs)
               ^^^^^^^^^^^^^^^^^^^^^^^^^^^^^^^^^^^^^^^^^^^^^^^^^^^^^^^^^^^^
  File "D:\Djnago_pwh\github_portfolio\django-tailwind-blog-main\home\views.py", line 74, in contact
    if validate_email(email, check_mx=True, smtp_timeout=10, verify=True):
       ^^^^^^^^^^^^^^^^^^^^^^^^^^^^^^^^^^^^^^^^^^^^^^^^^^^^^^^^^^^^^^^^^^
  File "D:\Djnago_pwh\github_portfolio\django-tailwind-blog-main\portfolio_venv\Lib\site-packages\validate_email.py", line 131, in validate_email
    raise Exception('For check the mx records or check if the email exists you must '
Exception: For check the mx records or check if the email exists you must have installed pyDNS python package
"POST /contact HTTP/1.1" 500 76913
Internal Server Error: /contact
Traceback (most recent call last):
  File "D:\Djnago_pwh\github_portfolio\django-tailwind-blog-main\portfolio_venv\Lib\site-packages\django\core\handlers\exception.py", line 55, in inner
    response = get_response(request)
               ^^^^^^^^^^^^^^^^^^^^^
  File "D:\Djnago_pwh\github_portfolio\django-tailwind-blog-main\portfolio_venv\Lib\site-packages\django\core\handlers\base.py", line 197, in _get_response
    response = wrapped_callback(request, *callback_args, **callback_kwargs)
               ^^^^^^^^^^^^^^^^^^^^^^^^^^^^^^^^^^^^^^^^^^^^^^^^^^^^^^^^^^^^
  File "D:\Djnago_pwh\github_portfolio\django-tailwind-blog-main\home\views.py", line 74, in contact
    if validate_email(email, check_mx=True, smtp_timeout=10, verify=True):
       ^^^^^^^^^^^^^^^^^^^^^^^^^^^^^^^^^^^^^^^^^^^^^^^^^^^^^^^^^^^^^^^^^^
  File "D:\Djnago_pwh\github_portfolio\django-tailwind-blog-main\portfolio_venv\Lib\site-packages\validate_email.py", line 131, in validate_email
    raise Exception('For check the mx records or check if the email exists you must '
Exception: For check the mx records or check if the email exists you must have installed pyDNS python package
"POST /contact HTTP/1.1" 500 76782
Internal Server Error: /contact
Traceback (most recent call last):
  File "D:\Djnago_pwh\github_portfolio\django-tailwind-blog-main\portfolio_venv\Lib\site-packages\django\core\handlers\exception.py", line 55, in inner
    response = get_response(request)
               ^^^^^^^^^^^^^^^^^^^^^
  File "D:\Djnago_pwh\github_portfolio\django-tailwind-blog-main\portfolio_venv\Lib\site-packages\django\core\handlers\base.py", line 197, in _get_response
    response = wrapped_callback(request, *callback_args, **callback_kwargs)
               ^^^^^^^^^^^^^^^^^^^^^^^^^^^^^^^^^^^^^^^^^^^^^^^^^^^^^^^^^^^^
  File "D:\Djnago_pwh\github_portfolio\django-tailwind-blog-main\home\views.py", line 74, in contact
    if validate_email(email, check_mx=True, smtp_timeout=10, verify=True):
       ^^^^^^^^^^^^^^^^^^^^^^^^^^^^^^^^^^^^^^^^^^^^^^^^^^^^^^^^^^^^^^^^^^
  File "D:\Djnago_pwh\github_portfolio\django-tailwind-blog-main\portfolio_venv\Lib\site-packages\validate_email.py", line 131, in validate_email
    raise Exception('For check the mx records or check if the email exists you must '
Exception: For check the mx records or check if the email exists you must have installed pyDNS python package
"POST /contact HTTP/1.1" 500 76913
Internal Server Error: /contact
Traceback (most recent call last):
  File "D:\Djnago_pwh\github_portfolio\django-tailwind-blog-main\portfolio_venv\Lib\site-packages\django\core\handlers\exception.py", line 55, in inner
    response = get_response(request)
               ^^^^^^^^^^^^^^^^^^^^^
  File "D:\Djnago_pwh\github_portfolio\django-tailwind-blog-main\portfolio_venv\Lib\site-packages\django\core\handlers\base.py", line 197, in _get_response
    response = wrapped_callback(request, *callback_args, **callback_kwargs)
               ^^^^^^^^^^^^^^^^^^^^^^^^^^^^^^^^^^^^^^^^^^^^^^^^^^^^^^^^^^^^
  File "D:\Djnago_pwh\github_portfolio\django-tailwind-blog-main\home\views.py", line 140, in contact
    if verify_email(email):
       ^^^^^^^^^^^^^^^^^^^
  File "D:\Djnago_pwh\github_portfolio\django-tailwind-blog-main\portfolio_venv\Lib\site-packages\verify_email\verify_email.py", line 103, in verify_email
    loop = asyncio.get_event_loop()
           ^^^^^^^^^^^^^^^^^^^^^^^^
  File "C:\Users\HP\AppData\Local\Programs\Python\Python311\Lib\asyncio\events.py", line 677, in get_event_loop
    raise RuntimeError('There is no current event loop in thread %r.'
RuntimeError: There is no current event loop in thread 'Thread-3 (process_request_thread)'.
"POST /contact HTTP/1.1" 500 79909
Internal Server Error: /contact
Traceback (most recent call last):
  File "D:\Djnago_pwh\github_portfolio\django-tailwind-blog-main\portfolio_venv\Lib\site-packages\django\core\handlers\exception.py", line 55, in inner
    response = get_response(request)
               ^^^^^^^^^^^^^^^^^^^^^
  File "D:\Djnago_pwh\github_portfolio\django-tailwind-blog-main\portfolio_venv\Lib\site-packages\django\core\handlers\base.py", line 197, in _get_response
    response = wrapped_callback(request, *callback_args, **callback_kwargs)
               ^^^^^^^^^^^^^^^^^^^^^^^^^^^^^^^^^^^^^^^^^^^^^^^^^^^^^^^^^^^^
  File "D:\Djnago_pwh\github_portfolio\django-tailwind-blog-main\home\views.py", line 184, in contact
    if verify_email(email):
       ^^^^^^^^^^^^^^^^^^^
  File "D:\Djnago_pwh\github_portfolio\django-tailwind-blog-main\portfolio_venv\Lib\site-packages\verify_email\verify_email.py", line 103, in verify_email
    loop = asyncio.get_event_loop()
           ^^^^^^^^^^^^^^^^^^^^^^^^
  File "C:\Users\HP\AppData\Local\Programs\Python\Python311\Lib\asyncio\events.py", line 677, in get_event_loop
    raise RuntimeError('There is no current event loop in thread %r.'
RuntimeError: There is no current event loop in thread 'Thread-2 (process_request_thread)'.
"POST /contact HTTP/1.1" 500 79812
Internal Server Error: /contact
Traceback (most recent call last):
  File "D:\Djnago_pwh\github_portfolio\django-tailwind-blog-main\portfolio_venv\Lib\site-packages\django\core\handlers\exception.py", line 55, in inner
    response = get_response(request)
               ^^^^^^^^^^^^^^^^^^^^^
  File "D:\Djnago_pwh\github_portfolio\django-tailwind-blog-main\portfolio_venv\Lib\site-packages\django\core\handlers\base.py", line 197, in _get_response
    response = wrapped_callback(request, *callback_args, **callback_kwargs)
               ^^^^^^^^^^^^^^^^^^^^^^^^^^^^^^^^^^^^^^^^^^^^^^^^^^^^^^^^^^^^
  File "D:\Djnago_pwh\github_portfolio\django-tailwind-blog-main\home\views.py", line 184, in contact
    if verify_email(email):
       ^^^^^^^^^^^^^^^^^^^
  File "D:\Djnago_pwh\github_portfolio\django-tailwind-blog-main\portfolio_venv\Lib\site-packages\verify_email\verify_email.py", line 103, in verify_email
    loop = asyncio.get_event_loop()
           ^^^^^^^^^^^^^^^^^^^^^^^^
  File "C:\Users\HP\AppData\Local\Programs\Python\Python311\Lib\asyncio\events.py", line 677, in get_event_loop
    raise RuntimeError('There is no current event loop in thread %r.'
RuntimeError: There is no current event loop in thread 'Thread-4 (process_request_thread)'.
"POST /contact HTTP/1.1" 500 79943
Internal Server Error: /contact
Traceback (most recent call last):
  File "D:\Djnago_pwh\github_portfolio\django-tailwind-blog-main\portfolio_venv\Lib\site-packages\django\core\handlers\exception.py", line 55, in inner
    response = get_response(request)
               ^^^^^^^^^^^^^^^^^^^^^
  File "D:\Djnago_pwh\github_portfolio\django-tailwind-blog-main\portfolio_venv\Lib\site-packages\django\core\handlers\base.py", line 197, in _get_response
    response = wrapped_callback(request, *callback_args, **callback_kwargs)
               ^^^^^^^^^^^^^^^^^^^^^^^^^^^^^^^^^^^^^^^^^^^^^^^^^^^^^^^^^^^^
  File "D:\Djnago_pwh\github_portfolio\django-tailwind-blog-main\home\views.py", line 191, in contact
    with concurrent.futures.ThreadPoolExecutor() as executor:
         ^^^^^^^^^^
NameError: name 'concurrent' is not defined
"POST /contact HTTP/1.1" 500 71612
Internal Server Error: /contact
Traceback (most recent call last):
  File "D:\Djnago_pwh\github_portfolio\django-tailwind-blog-main\portfolio_venv\Lib\site-packages\django\core\handlers\exception.py", line 55, in inner
    response = get_response(request)
               ^^^^^^^^^^^^^^^^^^^^^
  File "D:\Djnago_pwh\github_portfolio\django-tailwind-blog-main\portfolio_venv\Lib\site-packages\django\core\handlers\base.py", line 197, in _get_response
    response = wrapped_callback(request, *callback_args, **callback_kwargs)
               ^^^^^^^^^^^^^^^^^^^^^^^^^^^^^^^^^^^^^^^^^^^^^^^^^^^^^^^^^^^^
  File "D:\Djnago_pwh\github_portfolio\django-tailwind-blog-main\home\views.py", line 195, in contact
    email_exists = executor.submit(verify_email_async, email).result()
                   ^^^^^^^^^^^^^^^^^^^^^^^^^^^^^^^^^^^^^^^^^^^^^^^^^^^
  File "C:\Users\HP\AppData\Local\Programs\Python\Python311\Lib\concurrent\futures\_base.py", line 456, in result
    return self.__get_result()
           ^^^^^^^^^^^^^^^^^^^
  File "C:\Users\HP\AppData\Local\Programs\Python\Python311\Lib\concurrent\futures\_base.py", line 401, in __get_result
    raise self._exception
  File "C:\Users\HP\AppData\Local\Programs\Python\Python311\Lib\concurrent\futures\thread.py", line 58, in run
    result = self.fn(*self.args, **self.kwargs)
             ^^^^^^^^^^^^^^^^^^^^^^^^^^^^^^^^^^
  File "D:\Djnago_pwh\github_portfolio\django-tailwind-blog-main\home\views.py", line 174, in verify_email_async
    result = loop.run_until_complete(verify_email(email))
                                     ^^^^^^^^^^^^^^^^^^^
  File "D:\Djnago_pwh\github_portfolio\django-tailwind-blog-main\portfolio_venv\Lib\site-packages\verify_email\verify_email.py", line 103, in verify_email
    loop = asyncio.get_event_loop()
           ^^^^^^^^^^^^^^^^^^^^^^^^
  File "C:\Users\HP\AppData\Local\Programs\Python\Python311\Lib\asyncio\events.py", line 677, in get_event_loop
    raise RuntimeError('There is no current event loop in thread %r.'
RuntimeError: There is no current event loop in thread 'ThreadPoolExecutor-1_0'.
"POST /contact HTTP/1.1" 500 94422
Internal Server Error: /contact
Traceback (most recent call last):
  File "D:\Djnago_pwh\github_portfolio\django-tailwind-blog-main\portfolio_venv\Lib\site-packages\django\core\handlers\exception.py", line 55, in inner
    response = get_response(request)
               ^^^^^^^^^^^^^^^^^^^^^
  File "D:\Djnago_pwh\github_portfolio\django-tailwind-blog-main\portfolio_venv\Lib\site-packages\django\core\handlers\base.py", line 197, in _get_response
    response = wrapped_callback(request, *callback_args, **callback_kwargs)
               ^^^^^^^^^^^^^^^^^^^^^^^^^^^^^^^^^^^^^^^^^^^^^^^^^^^^^^^^^^^^
  File "D:\Djnago_pwh\github_portfolio\django-tailwind-blog-main\home\views.py", line 195, in contact
    email_exists = executor.submit(verify_email_async, email).result()
                   ^^^^^^^^^^^^^^^^^^^^^^^^^^^^^^^^^^^^^^^^^^^^^^^^^^^
  File "C:\Users\HP\AppData\Local\Programs\Python\Python311\Lib\concurrent\futures\_base.py", line 456, in result
    return self.__get_result()
           ^^^^^^^^^^^^^^^^^^^
  File "C:\Users\HP\AppData\Local\Programs\Python\Python311\Lib\concurrent\futures\_base.py", line 401, in __get_result
    raise self._exception
  File "C:\Users\HP\AppData\Local\Programs\Python\Python311\Lib\concurrent\futures\thread.py", line 58, in run
    result = self.fn(*self.args, **self.kwargs)
             ^^^^^^^^^^^^^^^^^^^^^^^^^^^^^^^^^^
  File "D:\Djnago_pwh\github_portfolio\django-tailwind-blog-main\home\views.py", line 174, in verify_email_async
    result = loop.run_until_complete(verify_email(email))
                                     ^^^^^^^^^^^^^^^^^^^
  File "D:\Djnago_pwh\github_portfolio\django-tailwind-blog-main\portfolio_venv\Lib\site-packages\verify_email\verify_email.py", line 103, in verify_email
    loop = asyncio.get_event_loop()
           ^^^^^^^^^^^^^^^^^^^^^^^^
  File "C:\Users\HP\AppData\Local\Programs\Python\Python311\Lib\asyncio\events.py", line 677, in get_event_loop
    raise RuntimeError('There is no current event loop in thread %r.'
RuntimeError: There is no current event loop in thread 'ThreadPoolExecutor-2_0'.
"POST /contact HTTP/1.1" 500 94561
Internal Server Error: /contact
Traceback (most recent call last):
  File "D:\Djnago_pwh\github_portfolio\django-tailwind-blog-main\portfolio_venv\Lib\site-packages\django\core\handlers\exception.py", line 55, in inner
    response = get_response(request)
               ^^^^^^^^^^^^^^^^^^^^^
  File "D:\Djnago_pwh\github_portfolio\django-tailwind-blog-main\portfolio_venv\Lib\site-packages\django\core\handlers\base.py", line 197, in _get_response
    response = wrapped_callback(request, *callback_args, **callback_kwargs)
               ^^^^^^^^^^^^^^^^^^^^^^^^^^^^^^^^^^^^^^^^^^^^^^^^^^^^^^^^^^^^
  File "D:\Djnago_pwh\github_portfolio\django-tailwind-blog-main\home\views.py", line 195, in contact
    email_exists = executor.submit(asyncio.run, verify_email_async(email)).result()
                   ^^^^^^^^^^^^^^^^^^^^^^^^^^^^^^^^^^^^^^^^^^^^^^^^^^^^^^^^^^^^^^^^
  File "C:\Users\HP\AppData\Local\Programs\Python\Python311\Lib\concurrent\futures\_base.py", line 456, in result
    return self.__get_result()
           ^^^^^^^^^^^^^^^^^^^
  File "C:\Users\HP\AppData\Local\Programs\Python\Python311\Lib\concurrent\futures\_base.py", line 401, in __get_result
    raise self._exception
  File "C:\Users\HP\AppData\Local\Programs\Python\Python311\Lib\concurrent\futures\thread.py", line 58, in run
    result = self.fn(*self.args, **self.kwargs)
             ^^^^^^^^^^^^^^^^^^^^^^^^^^^^^^^^^^
  File "C:\Users\HP\AppData\Local\Programs\Python\Python311\Lib\asyncio\runners.py", line 190, in run
    return runner.run(main)
           ^^^^^^^^^^^^^^^^
  File "C:\Users\HP\AppData\Local\Programs\Python\Python311\Lib\asyncio\runners.py", line 118, in run
    return self._loop.run_until_complete(task)
           ^^^^^^^^^^^^^^^^^^^^^^^^^^^^^^^^^^^
  File "C:\Users\HP\AppData\Local\Programs\Python\Python311\Lib\asyncio\base_events.py", line 653, in run_until_complete
    return future.result()
           ^^^^^^^^^^^^^^^
  File "D:\Djnago_pwh\github_portfolio\django-tailwind-blog-main\home\views.py", line 174, in verify_email_async
    result = await verify_email(email)
                   ^^^^^^^^^^^^^^^^^^^
  File "D:\Djnago_pwh\github_portfolio\django-tailwind-blog-main\portfolio_venv\Lib\site-packages\verify_email\verify_email.py", line 106, in verify_email
    resp = loop.run_until_complete(_verify_email(email, timeout, verify))
           ^^^^^^^^^^^^^^^^^^^^^^^^^^^^^^^^^^^^^^^^^^^^^^^^^^^^^^^^^^^^^^
  File "C:\Users\HP\AppData\Local\Programs\Python\Python311\Lib\asyncio\base_events.py", line 629, in run_until_complete
    self._check_running()
  File "C:\Users\HP\AppData\Local\Programs\Python\Python311\Lib\asyncio\base_events.py", line 588, in _check_running
    raise RuntimeError('This event loop is already running')
RuntimeError: This event loop is already running
"POST /contact HTTP/1.1" 500 111284
Internal Server Error: /contact
Traceback (most recent call last):
  File "D:\Djnago_pwh\github_portfolio\django-tailwind-blog-main\portfolio_venv\Lib\site-packages\django\core\handlers\exception.py", line 55, in inner
    response = get_response(request)
               ^^^^^^^^^^^^^^^^^^^^^
  File "D:\Djnago_pwh\github_portfolio\django-tailwind-blog-main\portfolio_venv\Lib\site-packages\django\core\handlers\base.py", line 197, in _get_response
    response = wrapped_callback(request, *callback_args, **callback_kwargs)
               ^^^^^^^^^^^^^^^^^^^^^^^^^^^^^^^^^^^^^^^^^^^^^^^^^^^^^^^^^^^^
  File "D:\Djnago_pwh\github_portfolio\django-tailwind-blog-main\home\views.py", line 193, in contact
    email_exists = loop.run_until_complete(verify_email_async(email))
                   ^^^^^^^^^^^^^^^^^^^^^^^^^^^^^^^^^^^^^^^^^^^^^^^^^^
  File "C:\Users\HP\AppData\Local\Programs\Python\Python311\Lib\asyncio\base_events.py", line 653, in run_until_complete
    return future.result()
           ^^^^^^^^^^^^^^^
  File "D:\Djnago_pwh\github_portfolio\django-tailwind-blog-main\home\views.py", line 172, in verify_email_async
    result = await verify_email(email)
                   ^^^^^^^^^^^^^^^^^^^
  File "D:\Djnago_pwh\github_portfolio\django-tailwind-blog-main\portfolio_venv\Lib\site-packages\verify_email\verify_email.py", line 106, in verify_email
    resp = loop.run_until_complete(_verify_email(email, timeout, verify))
           ^^^^^^^^^^^^^^^^^^^^^^^^^^^^^^^^^^^^^^^^^^^^^^^^^^^^^^^^^^^^^^
  File "C:\Users\HP\AppData\Local\Programs\Python\Python311\Lib\asyncio\base_events.py", line 629, in run_until_complete
    self._check_running()
  File "C:\Users\HP\AppData\Local\Programs\Python\Python311\Lib\asyncio\base_events.py", line 588, in _check_running
    raise RuntimeError('This event loop is already running')
RuntimeError: This event loop is already running
"POST /contact HTTP/1.1" 500 92158
Internal Server Error: /contact
Traceback (most recent call last):
  File "D:\Djnago_pwh\github_portfolio\django-tailwind-blog-main\portfolio_venv\Lib\site-packages\django\core\handlers\exception.py", line 55, in inner
    response = get_response(request)
               ^^^^^^^^^^^^^^^^^^^^^
  File "D:\Djnago_pwh\github_portfolio\django-tailwind-blog-main\portfolio_venv\Lib\site-packages\django\core\handlers\base.py", line 197, in _get_response
    response = wrapped_callback(request, *callback_args, **callback_kwargs)
               ^^^^^^^^^^^^^^^^^^^^^^^^^^^^^^^^^^^^^^^^^^^^^^^^^^^^^^^^^^^^
  File "D:\Djnago_pwh\github_portfolio\django-tailwind-blog-main\home\views.py", line 194, in contact
    email_exists = loop.run_until_complete(verify_email_async(email))
                   ^^^^^^^^^^^^^^^^^^^^^^^^^^^^^^^^^^^^^^^^^^^^^^^^^^
  File "C:\Users\HP\AppData\Local\Programs\Python\Python311\Lib\asyncio\base_events.py", line 653, in run_until_complete
    return future.result()
           ^^^^^^^^^^^^^^^
  File "D:\Djnago_pwh\github_portfolio\django-tailwind-blog-main\home\views.py", line 172, in verify_email_async
    result = await verify_email(email)
                   ^^^^^^^^^^^^^^^^^^^
  File "D:\Djnago_pwh\github_portfolio\django-tailwind-blog-main\portfolio_venv\Lib\site-packages\verify_email\verify_email.py", line 106, in verify_email
    resp = loop.run_until_complete(_verify_email(email, timeout, verify))
           ^^^^^^^^^^^^^^^^^^^^^^^^^^^^^^^^^^^^^^^^^^^^^^^^^^^^^^^^^^^^^^
  File "C:\Users\HP\AppData\Local\Programs\Python\Python311\Lib\asyncio\base_events.py", line 629, in run_until_complete
    self._check_running()
  File "C:\Users\HP\AppData\Local\Programs\Python\Python311\Lib\asyncio\base_events.py", line 588, in _check_running
    raise RuntimeError('This event loop is already running')
RuntimeError: This event loop is already running
"POST /contact HTTP/1.1" 500 92193
Internal Server Error: /contact
Traceback (most recent call last):
  File "D:\Djnago_pwh\github_portfolio\django-tailwind-blog-main\portfolio_venv\Lib\site-packages\django\core\handlers\exception.py", line 55, in inner
    response = get_response(request)
               ^^^^^^^^^^^^^^^^^^^^^
  File "D:\Djnago_pwh\github_portfolio\django-tailwind-blog-main\portfolio_venv\Lib\site-packages\django\core\handlers\base.py", line 197, in _get_response
    response = wrapped_callback(request, *callback_args, **callback_kwargs)
               ^^^^^^^^^^^^^^^^^^^^^^^^^^^^^^^^^^^^^^^^^^^^^^^^^^^^^^^^^^^^
  File "D:\Djnago_pwh\github_portfolio\django-tailwind-blog-main\home\views.py", line 194, in contact
    email_exists = loop.run_until_complete(verify_email_async(email))
                   ^^^^^^^^^^^^^^^^^^^^^^^^^^^^^^^^^^^^^^^^^^^^^^^^^^
  File "C:\Users\HP\AppData\Local\Programs\Python\Python311\Lib\asyncio\base_events.py", line 653, in run_until_complete
    return future.result()
           ^^^^^^^^^^^^^^^
  File "D:\Djnago_pwh\github_portfolio\django-tailwind-blog-main\home\views.py", line 172, in verify_email_async
    result = await verify_email(email)
                   ^^^^^^^^^^^^^^^^^^^
  File "D:\Djnago_pwh\github_portfolio\django-tailwind-blog-main\portfolio_venv\Lib\site-packages\verify_email\verify_email.py", line 106, in verify_email
    resp = loop.run_until_complete(_verify_email(email, timeout, verify))
           ^^^^^^^^^^^^^^^^^^^^^^^^^^^^^^^^^^^^^^^^^^^^^^^^^^^^^^^^^^^^^^
  File "C:\Users\HP\AppData\Local\Programs\Python\Python311\Lib\asyncio\base_events.py", line 629, in run_until_complete
    self._check_running()
  File "C:\Users\HP\AppData\Local\Programs\Python\Python311\Lib\asyncio\base_events.py", line 588, in _check_running
    raise RuntimeError('This event loop is already running')
RuntimeError: This event loop is already running
"POST /contact HTTP/1.1" 500 92330
Internal Server Error: /contact
Traceback (most recent call last):
  File "D:\Djnago_pwh\github_portfolio\django-tailwind-blog-main\portfolio_venv\Lib\site-packages\django\core\handlers\exception.py", line 55, in inner
    response = get_response(request)
               ^^^^^^^^^^^^^^^^^^^^^
  File "D:\Djnago_pwh\github_portfolio\django-tailwind-blog-main\portfolio_venv\Lib\site-packages\django\core\handlers\base.py", line 197, in _get_response
    response = wrapped_callback(request, *callback_args, **callback_kwargs)
               ^^^^^^^^^^^^^^^^^^^^^^^^^^^^^^^^^^^^^^^^^^^^^^^^^^^^^^^^^^^^
  File "D:\Djnago_pwh\github_portfolio\django-tailwind-blog-main\home\views.py", line 194, in contact
    email_exists = loop.run_until_complete(verify_email_async(email))
                   ^^^^^^^^^^^^^^^^^^^^^^^^^^^^^^^^^^^^^^^^^^^^^^^^^^
  File "C:\Users\HP\AppData\Local\Programs\Python\Python311\Lib\asyncio\base_events.py", line 653, in run_until_complete
    return future.result()
           ^^^^^^^^^^^^^^^
  File "D:\Djnago_pwh\github_portfolio\django-tailwind-blog-main\home\views.py", line 172, in verify_email_async
    result = await verify_email(email)
                   ^^^^^^^^^^^^^^^^^^^
  File "D:\Djnago_pwh\github_portfolio\django-tailwind-blog-main\portfolio_venv\Lib\site-packages\verify_email\verify_email.py", line 106, in verify_email
    resp = loop.run_until_complete(_verify_email(email, timeout, verify))
           ^^^^^^^^^^^^^^^^^^^^^^^^^^^^^^^^^^^^^^^^^^^^^^^^^^^^^^^^^^^^^^
  File "C:\Users\HP\AppData\Local\Programs\Python\Python311\Lib\asyncio\base_events.py", line 629, in run_until_complete
    self._check_running()
  File "C:\Users\HP\AppData\Local\Programs\Python\Python311\Lib\asyncio\base_events.py", line 588, in _check_running
    raise RuntimeError('This event loop is already running')
RuntimeError: This event loop is already running
"POST /contact HTTP/1.1" 500 92199
Internal Server Error: /search/
Traceback (most recent call last):
  File "D:\Djnago_pwh\my_portfolio\django-portfolio\portfolio_venv\Lib\site-packages\django\core\handlers\exception.py", line 55, in inner
    response = get_response(request)
               ^^^^^^^^^^^^^^^^^^^^^
  File "D:\Djnago_pwh\my_portfolio\django-portfolio\portfolio_venv\Lib\site-packages\django\core\handlers\base.py", line 197, in _get_response
    response = wrapped_callback(request, *callback_args, **callback_kwargs)
               ^^^^^^^^^^^^^^^^^^^^^^^^^^^^^^^^^^^^^^^^^^^^^^^^^^^^^^^^^^^^
  File "D:\Djnago_pwh\my_portfolio\django-portfolio\home\views.py", line 115, in search
    return render(request, 'search.html', {'results': results, 'query': query, 'message': message})
           ^^^^^^^^^^^^^^^^^^^^^^^^^^^^^^^^^^^^^^^^^^^^^^^^^^^^^^^^^^^^^^^^^^^^^^^^^^^^^^^^^^^^^^^^
  File "D:\Djnago_pwh\my_portfolio\django-portfolio\portfolio_venv\Lib\site-packages\django\shortcuts.py", line 24, in render
    content = loader.render_to_string(template_name, context, request, using=using)
              ^^^^^^^^^^^^^^^^^^^^^^^^^^^^^^^^^^^^^^^^^^^^^^^^^^^^^^^^^^^^^^^^^^^^^
  File "D:\Djnago_pwh\my_portfolio\django-portfolio\portfolio_venv\Lib\site-packages\django\template\loader.py", line 61, in render_to_string
    template = get_template(template_name, using=using)
               ^^^^^^^^^^^^^^^^^^^^^^^^^^^^^^^^^^^^^^^^
  File "D:\Djnago_pwh\my_portfolio\django-portfolio\portfolio_venv\Lib\site-packages\django\template\loader.py", line 15, in get_template
    return engine.get_template(template_name)
           ^^^^^^^^^^^^^^^^^^^^^^^^^^^^^^^^^^
  File "D:\Djnago_pwh\my_portfolio\django-portfolio\portfolio_venv\Lib\site-packages\django\template\backends\django.py", line 34, in get_template
    return Template(self.engine.get_template(template_name), self)
                    ^^^^^^^^^^^^^^^^^^^^^^^^^^^^^^^^^^^^^^^
  File "D:\Djnago_pwh\my_portfolio\django-portfolio\portfolio_venv\Lib\site-packages\django\template\engine.py", line 175, in get_template
    template, origin = self.find_template(template_name)
                       ^^^^^^^^^^^^^^^^^^^^^^^^^^^^^^^^^
  File "D:\Djnago_pwh\my_portfolio\django-portfolio\portfolio_venv\Lib\site-packages\django\template\engine.py", line 157, in find_template
    template = loader.get_template(name, skip=skip)
               ^^^^^^^^^^^^^^^^^^^^^^^^^^^^^^^^^^^^
  File "D:\Djnago_pwh\my_portfolio\django-portfolio\portfolio_venv\Lib\site-packages\django\template\loaders\cached.py", line 57, in get_template
    template = super().get_template(template_name, skip)
               ^^^^^^^^^^^^^^^^^^^^^^^^^^^^^^^^^^^^^^^^^
  File "D:\Djnago_pwh\my_portfolio\django-portfolio\portfolio_venv\Lib\site-packages\django\template\loaders\base.py", line 28, in get_template
    return Template(
           ^^^^^^^^^
  File "D:\Djnago_pwh\my_portfolio\django-portfolio\portfolio_venv\Lib\site-packages\django\template\base.py", line 154, in __init__
    self.nodelist = self.compile_nodelist()
                    ^^^^^^^^^^^^^^^^^^^^^^^
  File "D:\Djnago_pwh\my_portfolio\django-portfolio\portfolio_venv\Lib\site-packages\django\template\base.py", line 200, in compile_nodelist
    return parser.parse()
           ^^^^^^^^^^^^^^
  File "D:\Djnago_pwh\my_portfolio\django-portfolio\portfolio_venv\Lib\site-packages\django\template\base.py", line 514, in parse
    self.extend_nodelist(nodelist, compiled_result, token)
  File "D:\Djnago_pwh\my_portfolio\django-portfolio\portfolio_venv\Lib\site-packages\django\template\base.py", line 531, in extend_nodelist
    raise self.error(
django.template.exceptions.TemplateSyntaxError: <ExtendsNode: extends 'base.html'> must be the first tag in the template.
"GET /search/?q=College%20Repository HTTP/1.1" 500 149859
Internal Server Error: /search/
Traceback (most recent call last):
  File "D:\Djnago_pwh\my_portfolio\django-portfolio\portfolio_venv\Lib\site-packages\django\core\handlers\exception.py", line 55, in inner
    response = get_response(request)
               ^^^^^^^^^^^^^^^^^^^^^
  File "D:\Djnago_pwh\my_portfolio\django-portfolio\portfolio_venv\Lib\site-packages\django\core\handlers\base.py", line 197, in _get_response
    response = wrapped_callback(request, *callback_args, **callback_kwargs)
               ^^^^^^^^^^^^^^^^^^^^^^^^^^^^^^^^^^^^^^^^^^^^^^^^^^^^^^^^^^^^
  File "D:\Djnago_pwh\my_portfolio\django-portfolio\home\views.py", line 104, in search
    query_list = query.split()
                 ^^^^^^^^^^^
AttributeError: 'NoneType' object has no attribute 'split'
"GET /search/? HTTP/1.1" 500 69721
Internal Server Error: /search/
Traceback (most recent call last):
  File "D:\Djnago_pwh\my_portfolio\django-portfolio\portfolio_venv\Lib\site-packages\django\core\handlers\exception.py", line 55, in inner
    response = get_response(request)
               ^^^^^^^^^^^^^^^^^^^^^
  File "D:\Djnago_pwh\my_portfolio\django-portfolio\portfolio_venv\Lib\site-packages\django\core\handlers\base.py", line 197, in _get_response
    response = wrapped_callback(request, *callback_args, **callback_kwargs)
               ^^^^^^^^^^^^^^^^^^^^^^^^^^^^^^^^^^^^^^^^^^^^^^^^^^^^^^^^^^^^
  File "D:\Djnago_pwh\my_portfolio\django-portfolio\home\views.py", line 120, in search
    query_list = query.split()
                 ^^^^^^^^^^^
AttributeError: 'NoneType' object has no attribute 'split'
"GET /search/? HTTP/1.1" 500 69639
Internal Server Error: /search/
Traceback (most recent call last):
  File "D:\Djnago_pwh\my_portfolio\django-portfolio\portfolio_venv\Lib\site-packages\django\core\handlers\exception.py", line 55, in inner
    response = get_response(request)
               ^^^^^^^^^^^^^^^^^^^^^
  File "D:\Djnago_pwh\my_portfolio\django-portfolio\portfolio_venv\Lib\site-packages\django\core\handlers\base.py", line 197, in _get_response
    response = wrapped_callback(request, *callback_args, **callback_kwargs)
               ^^^^^^^^^^^^^^^^^^^^^^^^^^^^^^^^^^^^^^^^^^^^^^^^^^^^^^^^^^^^
  File "D:\Djnago_pwh\my_portfolio\django-portfolio\home\views.py", line 120, in search
    query_list = query.split()
                 ^^^^^^^^^^^
AttributeError: 'NoneType' object has no attribute 'split'
"GET /search/? HTTP/1.1" 500 69770
Internal Server Error: /search/
Traceback (most recent call last):
  File "D:\Djnago_pwh\my_portfolio\django-portfolio\portfolio_venv\Lib\site-packages\django\core\handlers\exception.py", line 55, in inner
    response = get_response(request)
               ^^^^^^^^^^^^^^^^^^^^^
  File "D:\Djnago_pwh\my_portfolio\django-portfolio\portfolio_venv\Lib\site-packages\django\core\handlers\base.py", line 197, in _get_response
    response = wrapped_callback(request, *callback_args, **callback_kwargs)
               ^^^^^^^^^^^^^^^^^^^^^^^^^^^^^^^^^^^^^^^^^^^^^^^^^^^^^^^^^^^^
  File "D:\Djnago_pwh\my_portfolio\django-portfolio\home\views.py", line 120, in search
    query_list = query.split()
                 ^^^^^^^^^^^
AttributeError: 'NoneType' object has no attribute 'split'
"GET /search/? HTTP/1.1" 500 69770
Internal Server Error: /search/
Traceback (most recent call last):
  File "D:\Djnago_pwh\my_portfolio\django-portfolio\portfolio_venv\Lib\site-packages\django\core\handlers\exception.py", line 55, in inner
    response = get_response(request)
               ^^^^^^^^^^^^^^^^^^^^^
  File "D:\Djnago_pwh\my_portfolio\django-portfolio\portfolio_venv\Lib\site-packages\django\core\handlers\base.py", line 197, in _get_response
    response = wrapped_callback(request, *callback_args, **callback_kwargs)
               ^^^^^^^^^^^^^^^^^^^^^^^^^^^^^^^^^^^^^^^^^^^^^^^^^^^^^^^^^^^^
  File "D:\Djnago_pwh\my_portfolio\django-portfolio\home\views.py", line 120, in search
    query_list = query.split()
                 ^^^^^^^^^^^
AttributeError: 'NoneType' object has no attribute 'split'
"GET /search/? HTTP/1.1" 500 69770
Internal Server Error: /__reload__/events/
"GET /__reload__/events/ HTTP/1.1" 500 145
Internal Server Error: /__reload__/events/
"GET /__reload__/events/ HTTP/1.1" 500 145
Internal Server Error: /__reload__/events/
"GET /__reload__/events/ HTTP/1.1" 500 145
Internal Server Error: /__reload__/events/
"GET /__reload__/events/ HTTP/1.1" 500 145
Internal Server Error: /__reload__/events/
"GET /__reload__/events/ HTTP/1.1" 500 145
Internal Server Error: /__reload__/events/
"GET /__reload__/events/ HTTP/1.1" 500 145
Internal Server Error: /__reload__/events/
"GET /__reload__/events/ HTTP/1.1" 500 145
Internal Server Error: /__reload__/events/
"GET /__reload__/events/ HTTP/1.1" 500 145
Internal Server Error: /__reload__/events/
"GET /__reload__/events/ HTTP/1.1" 500 145
Internal Server Error: /__reload__/events/
"GET /__reload__/events/ HTTP/1.1" 500 145
Internal Server Error: /__reload__/events/
"GET /__reload__/events/ HTTP/1.1" 500 145
Internal Server Error: /__reload__/events/
"GET /__reload__/events/ HTTP/1.1" 500 145
Internal Server Error: /__reload__/events/
"GET /__reload__/events/ HTTP/1.1" 500 145
Internal Server Error: /__reload__/events/
"GET /__reload__/events/ HTTP/1.1" 500 145
Internal Server Error: /__reload__/events/
"GET /__reload__/events/ HTTP/1.1" 500 145
Internal Server Error: /__reload__/events/
"GET /__reload__/events/ HTTP/1.1" 500 145
Internal Server Error: /__reload__/events/
"GET /__reload__/events/ HTTP/1.1" 500 145
Internal Server Error: /__reload__/events/
"GET /__reload__/events/ HTTP/1.1" 500 145
Internal Server Error: /__reload__/events/
"GET /__reload__/events/ HTTP/1.1" 500 145
Internal Server Error: /__reload__/events/
"GET /__reload__/events/ HTTP/1.1" 500 145
Internal Server Error: /__reload__/events/
"GET /__reload__/events/ HTTP/1.1" 500 145
Internal Server Error: /__reload__/events/
"GET /__reload__/events/ HTTP/1.1" 500 145
Internal Server Error: /__reload__/events/
"GET /__reload__/events/ HTTP/1.1" 500 145
Internal Server Error: /__reload__/events/
"GET /__reload__/events/ HTTP/1.1" 500 145
Internal Server Error: /__reload__/events/
"GET /__reload__/events/ HTTP/1.1" 500 145
Internal Server Error: /__reload__/events/
"GET /__reload__/events/ HTTP/1.1" 500 145
Internal Server Error: /__reload__/events/
"GET /__reload__/events/ HTTP/1.1" 500 145
Internal Server Error: /__reload__/events/
"GET /__reload__/events/ HTTP/1.1" 500 145
Internal Server Error: /__reload__/events/
"GET /__reload__/events/ HTTP/1.1" 500 145
Internal Server Error: /__reload__/events/
"GET /__reload__/events/ HTTP/1.1" 500 145
Internal Server Error: /__reload__/events/
"GET /__reload__/events/ HTTP/1.1" 500 145
Internal Server Error: /__reload__/events/
"GET /__reload__/events/ HTTP/1.1" 500 145
Internal Server Error: /__reload__/events/
"GET /__reload__/events/ HTTP/1.1" 500 145
Internal Server Error: /__reload__/events/
"GET /__reload__/events/ HTTP/1.1" 500 145
Internal Server Error: /__reload__/events/
"GET /__reload__/events/ HTTP/1.1" 500 145
Internal Server Error: /__reload__/events/
"GET /__reload__/events/ HTTP/1.1" 500 145
Internal Server Error: /__reload__/events/
"GET /__reload__/events/ HTTP/1.1" 500 145
Internal Server Error: /__reload__/events/
"GET /__reload__/events/ HTTP/1.1" 500 145
Internal Server Error: /__reload__/events/
"GET /__reload__/events/ HTTP/1.1" 500 145
Internal Server Error: /__reload__/events/
"GET /__reload__/events/ HTTP/1.1" 500 145
Internal Server Error: /__reload__/events/
"GET /__reload__/events/ HTTP/1.1" 500 145
Internal Server Error: /__reload__/events/
"GET /__reload__/events/ HTTP/1.1" 500 145
Internal Server Error: /__reload__/events/
"GET /__reload__/events/ HTTP/1.1" 500 145
Internal Server Error: /__reload__/events/
"GET /__reload__/events/ HTTP/1.1" 500 145
Internal Server Error: /__reload__/events/
"GET /__reload__/events/ HTTP/1.1" 500 145
Internal Server Error: /__reload__/events/
"GET /__reload__/events/ HTTP/1.1" 500 145
Internal Server Error: /__reload__/events/
"GET /__reload__/events/ HTTP/1.1" 500 145
Internal Server Error: /__reload__/events/
"GET /__reload__/events/ HTTP/1.1" 500 145
Internal Server Error: /__reload__/events/
"GET /__reload__/events/ HTTP/1.1" 500 145
Internal Server Error: /__reload__/events/
"GET /__reload__/events/ HTTP/1.1" 500 145
Internal Server Error: /__reload__/events/
"GET /__reload__/events/ HTTP/1.1" 500 145
Internal Server Error: /__reload__/events/
"GET /__reload__/events/ HTTP/1.1" 500 145
Internal Server Error: /__reload__/events/
"GET /__reload__/events/ HTTP/1.1" 500 145
Internal Server Error: /__reload__/events/
"GET /__reload__/events/ HTTP/1.1" 500 145
Internal Server Error: /__reload__/events/
"GET /__reload__/events/ HTTP/1.1" 500 145
Internal Server Error: /__reload__/events/
"GET /__reload__/events/ HTTP/1.1" 500 145
Internal Server Error: /__reload__/events/
"GET /__reload__/events/ HTTP/1.1" 500 145
Internal Server Error: /__reload__/events/
"GET /__reload__/events/ HTTP/1.1" 500 145
Internal Server Error: /__reload__/events/
"GET /__reload__/events/ HTTP/1.1" 500 145
Internal Server Error: /__reload__/events/
"GET /__reload__/events/ HTTP/1.1" 500 145
Internal Server Error: /__reload__/events/
"GET /__reload__/events/ HTTP/1.1" 500 145
Internal Server Error: /__reload__/events/
"GET /__reload__/events/ HTTP/1.1" 500 145
Internal Server Error: /__reload__/events/
"GET /__reload__/events/ HTTP/1.1" 500 145
Internal Server Error: /__reload__/events/
"GET /__reload__/events/ HTTP/1.1" 500 145
Internal Server Error: /__reload__/events/
"GET /__reload__/events/ HTTP/1.1" 500 145
Internal Server Error: /__reload__/events/
"GET /__reload__/events/ HTTP/1.1" 500 145
Internal Server Error: /__reload__/events/
"GET /__reload__/events/ HTTP/1.1" 500 145
Internal Server Error: /__reload__/events/
"GET /__reload__/events/ HTTP/1.1" 500 145
Internal Server Error: /__reload__/events/
"GET /__reload__/events/ HTTP/1.1" 500 145
Internal Server Error: /__reload__/events/
"GET /__reload__/events/ HTTP/1.1" 500 145
Internal Server Error: /__reload__/events/
"GET /__reload__/events/ HTTP/1.1" 500 145
Internal Server Error: /__reload__/events/
"GET /__reload__/events/ HTTP/1.1" 500 145
Internal Server Error: /__reload__/events/
"GET /__reload__/events/ HTTP/1.1" 500 145
Internal Server Error: /__reload__/events/
"GET /__reload__/events/ HTTP/1.1" 500 145
Internal Server Error: /__reload__/events/
"GET /__reload__/events/ HTTP/1.1" 500 145
Internal Server Error: /__reload__/events/
"GET /__reload__/events/ HTTP/1.1" 500 145
Internal Server Error: /__reload__/events/
"GET /__reload__/events/ HTTP/1.1" 500 145
Internal Server Error: /__reload__/events/
"GET /__reload__/events/ HTTP/1.1" 500 145
Internal Server Error: /__reload__/events/
"GET /__reload__/events/ HTTP/1.1" 500 145
Internal Server Error: /__reload__/events/
"GET /__reload__/events/ HTTP/1.1" 500 145
Internal Server Error: /__reload__/events/
"GET /__reload__/events/ HTTP/1.1" 500 145
Internal Server Error: /__reload__/events/
"GET /__reload__/events/ HTTP/1.1" 500 145
Internal Server Error: /__reload__/events/
"GET /__reload__/events/ HTTP/1.1" 500 145
Internal Server Error: /__reload__/events/
"GET /__reload__/events/ HTTP/1.1" 500 145
Internal Server Error: /__reload__/events/
"GET /__reload__/events/ HTTP/1.1" 500 145
Internal Server Error: /__reload__/events/
"GET /__reload__/events/ HTTP/1.1" 500 145
Internal Server Error: /__reload__/events/
"GET /__reload__/events/ HTTP/1.1" 500 145
Internal Server Error: /__reload__/events/
"GET /__reload__/events/ HTTP/1.1" 500 145
Internal Server Error: /__reload__/events/
"GET /__reload__/events/ HTTP/1.1" 500 145
Internal Server Error: /__reload__/events/
"GET /__reload__/events/ HTTP/1.1" 500 145
Internal Server Error: /__reload__/events/
"GET /__reload__/events/ HTTP/1.1" 500 145
Internal Server Error: /__reload__/events/
"GET /__reload__/events/ HTTP/1.1" 500 145
Internal Server Error: /__reload__/events/
"GET /__reload__/events/ HTTP/1.1" 500 145
Internal Server Error: /__reload__/events/
"GET /__reload__/events/ HTTP/1.1" 500 145
Internal Server Error: /__reload__/events/
"GET /__reload__/events/ HTTP/1.1" 500 145
Internal Server Error: /__reload__/events/
"GET /__reload__/events/ HTTP/1.1" 500 145
Internal Server Error: /__reload__/events/
"GET /__reload__/events/ HTTP/1.1" 500 145
Internal Server Error: /__reload__/events/
"GET /__reload__/events/ HTTP/1.1" 500 145
Internal Server Error: /__reload__/events/
"GET /__reload__/events/ HTTP/1.1" 500 145
Internal Server Error: /__reload__/events/
"GET /__reload__/events/ HTTP/1.1" 500 145
Internal Server Error: /__reload__/events/
"GET /__reload__/events/ HTTP/1.1" 500 145
Internal Server Error: /__reload__/events/
"GET /__reload__/events/ HTTP/1.1" 500 145
Internal Server Error: /__reload__/events/
"GET /__reload__/events/ HTTP/1.1" 500 145
Internal Server Error: /__reload__/events/
"GET /__reload__/events/ HTTP/1.1" 500 145
Internal Server Error: /__reload__/events/
"GET /__reload__/events/ HTTP/1.1" 500 145
Internal Server Error: /__reload__/events/
"GET /__reload__/events/ HTTP/1.1" 500 145
Internal Server Error: /__reload__/events/
"GET /__reload__/events/ HTTP/1.1" 500 145
Internal Server Error: /__reload__/events/
"GET /__reload__/events/ HTTP/1.1" 500 145
Internal Server Error: /__reload__/events/
"GET /__reload__/events/ HTTP/1.1" 500 145
Internal Server Error: /__reload__/events/
"GET /__reload__/events/ HTTP/1.1" 500 145
Internal Server Error: /__reload__/events/
"GET /__reload__/events/ HTTP/1.1" 500 145
Internal Server Error: /__reload__/events/
"GET /__reload__/events/ HTTP/1.1" 500 145
Internal Server Error: /__reload__/events/
"GET /__reload__/events/ HTTP/1.1" 500 145
Internal Server Error: /__reload__/events/
"GET /__reload__/events/ HTTP/1.1" 500 145
Internal Server Error: /__reload__/events/
"GET /__reload__/events/ HTTP/1.1" 500 145
Internal Server Error: /__reload__/events/
"GET /__reload__/events/ HTTP/1.1" 500 145
Internal Server Error: /__reload__/events/
"GET /__reload__/events/ HTTP/1.1" 500 145
Internal Server Error: /__reload__/events/
"GET /__reload__/events/ HTTP/1.1" 500 145
Internal Server Error: /__reload__/events/
"GET /__reload__/events/ HTTP/1.1" 500 145
Internal Server Error: /__reload__/events/
"GET /__reload__/events/ HTTP/1.1" 500 145
Internal Server Error: /__reload__/events/
"GET /__reload__/events/ HTTP/1.1" 500 145
Internal Server Error: /__reload__/events/
"GET /__reload__/events/ HTTP/1.1" 500 145
Internal Server Error: /__reload__/events/
"GET /__reload__/events/ HTTP/1.1" 500 145
Internal Server Error: /__reload__/events/
"GET /__reload__/events/ HTTP/1.1" 500 145
Internal Server Error: /__reload__/events/
"GET /__reload__/events/ HTTP/1.1" 500 145
Internal Server Error: /__reload__/events/
"GET /__reload__/events/ HTTP/1.1" 500 145
Internal Server Error: /__reload__/events/
"GET /__reload__/events/ HTTP/1.1" 500 145
Internal Server Error: /__reload__/events/
"GET /__reload__/events/ HTTP/1.1" 500 145
Internal Server Error: /__reload__/events/
"GET /__reload__/events/ HTTP/1.1" 500 145
Internal Server Error: /__reload__/events/
"GET /__reload__/events/ HTTP/1.1" 500 145
Internal Server Error: /__reload__/events/
"GET /__reload__/events/ HTTP/1.1" 500 145
Internal Server Error: /__reload__/events/
"GET /__reload__/events/ HTTP/1.1" 500 145
Internal Server Error: /__reload__/events/
"GET /__reload__/events/ HTTP/1.1" 500 145
Internal Server Error: /__reload__/events/
"GET /__reload__/events/ HTTP/1.1" 500 145
Internal Server Error: /__reload__/events/
"GET /__reload__/events/ HTTP/1.1" 500 145
Internal Server Error: /__reload__/events/
"GET /__reload__/events/ HTTP/1.1" 500 145
Internal Server Error: /__reload__/events/
"GET /__reload__/events/ HTTP/1.1" 500 145
Internal Server Error: /__reload__/events/
"GET /__reload__/events/ HTTP/1.1" 500 145
Internal Server Error: /__reload__/events/
"GET /__reload__/events/ HTTP/1.1" 500 145
Internal Server Error: /__reload__/events/
"GET /__reload__/events/ HTTP/1.1" 500 145
Internal Server Error: /__reload__/events/
"GET /__reload__/events/ HTTP/1.1" 500 145
Internal Server Error: /__reload__/events/
"GET /__reload__/events/ HTTP/1.1" 500 145
Internal Server Error: /__reload__/events/
"GET /__reload__/events/ HTTP/1.1" 500 145
Internal Server Error: /__reload__/events/
"GET /__reload__/events/ HTTP/1.1" 500 145
Internal Server Error: /__reload__/events/
"GET /__reload__/events/ HTTP/1.1" 500 145
Internal Server Error: /__reload__/events/
"GET /__reload__/events/ HTTP/1.1" 500 145
Internal Server Error: /__reload__/events/
"GET /__reload__/events/ HTTP/1.1" 500 145
Internal Server Error: /__reload__/events/
"GET /__reload__/events/ HTTP/1.1" 500 145
Internal Server Error: /__reload__/events/
"GET /__reload__/events/ HTTP/1.1" 500 145
Internal Server Error: /__reload__/events/
"GET /__reload__/events/ HTTP/1.1" 500 145
Internal Server Error: /__reload__/events/
"GET /__reload__/events/ HTTP/1.1" 500 145
Internal Server Error: /__reload__/events/
"GET /__reload__/events/ HTTP/1.1" 500 145
Internal Server Error: /__reload__/events/
"GET /__reload__/events/ HTTP/1.1" 500 145
Internal Server Error: /__reload__/events/
"GET /__reload__/events/ HTTP/1.1" 500 145
Internal Server Error: /__reload__/events/
"GET /__reload__/events/ HTTP/1.1" 500 145
Internal Server Error: /__reload__/events/
"GET /__reload__/events/ HTTP/1.1" 500 145
Internal Server Error: /__reload__/events/
"GET /__reload__/events/ HTTP/1.1" 500 145
